Workbook

Sheet Assumptions
B2: Apple Inc. — Assumptions
B3: USD millions. Latest source period: 2025-09-30.
B4: Start with History and check the latest actual figures. Then fill the yellow forecast cells below. Enter 0 when you intend none. A blank means missing, so the affected forecast stays blank.
B7: Forecast driver | D7: Last actual | F7: 2026 | G7: 2027 | H7: 2028 | I7: 2029 | J7: 2030 | L7: What to enter
B9: Revenue growth | D9: =IF(COUNT(Statements!F120)=1,IF(TRUE,Statements!F120,""),"") -> 0.064255118 | L9: Enter the annual change in sales. For 5%, type 5%.
B10: Gross profit margin | D10: =IF(COUNT(Statements!F121)=1,IF(TRUE,Statements!F121,""),"") -> 0.46905164 | L10: Gross profit divided by sales. This sets cost of sales.
B11: EBITDA margin | D11: =IF(COUNT(Statements!F122)=1,IF(TRUE,Statements!F122,""),"") -> 0.34781731 | L11: Profit before depreciation, interest and tax, divided by sales. Must not exceed gross margin.
B12: Tax rate on positive profit | D12: =IF(COUNT(Statements!F123)=1,IF(TRUE,Statements!F123,""),"") -> 0.15610002 | L12: Tax as a share of positive profit. Losses receive no automatic tax credit.
B13: Customer payment days | D13: =IF(COUNT(Statements!F124)=1,IF(TRUE,Statements!F124,""),"") -> 34.886991 | L13: Average days before customers pay. Receivables = sales / 365 × days.
B14: Inventory holding days | D14: =IF(COUNT(Statements!F125)=1,IF(TRUE,Statements!F125,""),"") -> 9.4454652 | L14: Inventory = cost of sales / 365 × days. Enter 0 if the business holds none.
B15: Supplier payment days | D15: =IF(COUNT(Statements!F126)=1,IF(TRUE,Statements!F126,""),"") -> 115.40052 | L15: Payables = cost of sales / 365 × days. Enter 0 if not used.
B16: Capital spending / revenue | D16: =IF(COUNT(Statements!F127)=1,IF(TRUE,Statements!F127,""),"") -> 0.030553079 | L16: Cash spent on fixed assets, divided by sales. Enter 0 for no spending.
B17: Depreciation / opening fixed assets | D17: =IF(COUNT(Statements!F128)=1,IF(TRUE,Statements!F128,""),"") -> 0.25608581 | L17: Rate applied to opening net fixed assets. New spending starts depreciating next year.
B18: Interest rate on opening debt | D18: =IF(COUNT(Statements!F129)=1,IF(TRUE,Statements!F129,""),"") | L18: Annual financing rate. Interest uses opening debt, avoiding a circular formula.
B19: Debt repayment / opening debt | D19: =IF(COUNT(Statements!F130)=1,IF(TRUE,Statements!F130,""),"") -> 0.1025237 | L19: Share of opening debt repaid during the year. Enter 0 for no repayment.
B20: New borrowing | D20: =IF(COUNT(Statements!F131)=1,IF(TRUE,Statements!F131,""),"") -> 4481 | L20: Amount of new debt, in the workbook currency units. Enter 0 if none.
... B23: Shares issued / (repurchased) | D23: =IF(COUNT(Statements!F134)=1,IF(TRUE,Statements!F134,""),"") -> -90711 | L23: Cash from new shares is positive; buybacks are negative. Enter 0 if none. Review the DCF share count separately.
B25: Unfilled forecast inputs | F25: =15-COUNT(F9:F23) -> 15 | G25: =15-COUNT(G9:G23) -> 15 | H25: =15-COUNT(H9:H23) -> 15 | I25: =15-COUNT(I9:I23) -> 15 | J25: =15-COUNT(J9:J23) -> 15
B29: DCF inputs. Enter these once, after the forecast. | C29: DCF inputs. Enter these once, after the forecast. | D29: DCF inputs. Enter these once, after the forecast. | E29: DCF inputs. Enter these once, after the forecast. | F29: DCF inputs. Enter these once, after the forecast. | G29: DCF inputs. Enter these once, after the forecast. | H29: DCF inputs. Enter these once, after the forecast. | I29: DCF inputs. Enter these once, after the forecast. | J29: DCF inputs. Enter these once, after the forecast.
B31: Discount rate (WACC) | L31: Required return for debt and equity together. Must be positive.
B32: Long-run cash flow growth | L32: Growth after year five. Must be greater than -100% and below WACC.
B33: Shares outstanding (millions) | L33: Enter your current fully diluted share count in millions. History shows the reported count.
B34: Other claims to deduct | L34: Claims on value other than the debt already shown. Include minority interests if relevant; enter 0 if none.
B35: Other non-operating assets to add | L35: Eligible assets not counted in cash or operating value. Do not add goodwill; enter 0 if none.
B36: Current share price (optional) | L36: Optional current price in USD per share. Leave blank if you do not need upside/downside.
B39: To keep assumptions the same each year, fill F9:F23, select F9:J23 and press Ctrl+R. Then adjust individual years if needed. The last-actual column is a reference, not a suggested forecast.
B43: How the basic forecast works: other assets and other liabilities stay at their latest actual amounts. Debt and fixed assets roll forward. There are no acquisitions, disposals, stock compensation or new tax-loss schedules. Negative cash remains visible; borrowing is never added automatically to make the model balance.

Sheet Statements
B2: Apple Inc. — Statements
B3: USD millions. Latest source period: 2025-09-30.
B4: Read down each statement. Black numbers calculate within this sheet; green numbers link to another sheet. Forecasts appear one year at a time after the inputs and opening figures are complete. Review checks are at the bottom.
B7: Financial year | D7: 2023 | E7: 2024 | F7: 2025 | H7: 2026 | I7: 2027 | J7: 2028 | K7: 2029 | L7: 2030
B8: Income statement | C8: Income statement | D8: Income statement | E8: Income statement | F8: Income statement | G8: Income statement | H8: Income statement | I8: Income statement | J8: Income statement | K8: Income statement | L8: Income statement
B9: Revenue | D9: =IF(COUNT(History!E9)=1,IF(TRUE,History!E9,""),"") -> 383285 | E9: =IF(COUNT(History!F9)=1,IF(TRUE,History!F9,""),"") -> 391035 | F9: =IF(COUNT(History!G9)=1,IF(TRUE,History!G9,""),"") -> 416161 | H9: =IF(Statements!H89,Statements!F9*(1+Assumptions!F9),"") | I9: =IF(Statements!I89,Statements!H9*(1+Assumptions!G9),"") | J9: =IF(Statements!J89,Statements!I9*(1+Assumptions!H9),"") | K9: =IF(Statements!K89,Statements!J9*(1+Assumptions!I9),"") | L9: =IF(Statements!L89,Statements!K9*(1+Assumptions!J9),"") | N9: Previous sales × (1 + revenue growth).
B10: Cost of sales | D10: =IF(COUNT(History!E10)=1,IF(TRUE,History!E10,""),"") -> 214137 | E10: =IF(COUNT(History!F10)=1,IF(TRUE,History!F10,""),"") -> 210352 | F10: =IF(COUNT(History!G10)=1,IF(TRUE,History!G10,""),"") -> 220960 | H10: =IF(Statements!H89,Statements!H9*(1-Assumptions!F10),"") | I10: =IF(Statements!I89,Statements!I9*(1-Assumptions!G10),"") | J10: =IF(Statements!J89,Statements!J9*(1-Assumptions!H10),"") | K10: =IF(Statements!K89,Statements!K9*(1-Assumptions!I10),"") | L10: =IF(Statements!L89,Statements!L9*(1-Assumptions!J10),"")
B11: Gross profit | D11: =IF(COUNT(Statements!D9,Statements!D10)=2,IF(TRUE,Statements!D9-Statements!D10,""),"") -> 169148 | E11: =IF(COUNT(Statements!E9,Statements!E10)=2,IF(TRUE,Statements!E9-Statements!E10,""),"") -> 180683 | F11: =IF(COUNT(Statements!F9,Statements!F10)=2,IF(TRUE,Statements!F9-Statements!F10,""),"") -> 195201 | H11: =IF(Statements!H89,Statements!H9-Statements!H10,"") | I11: =IF(Statements!I89,Statements!I9-Statements!I10,"") | J11: =IF(Statements!J89,Statements!J9-Statements!J10,"") | K11: =IF(Statements!K89,Statements!K9-Statements!K10,"") | L11: =IF(Statements!L89,Statements!L9-Statements!L10,"")
B12: Cash operating costs (derived) | D12: =IF(COUNT(Statements!D11,Statements!D13)=2,IF(TRUE,Statements!D11-Statements!D13,""),"") -> 43328 | E12: =IF(COUNT(Statements!E11,Statements!E13)=2,IF(TRUE,Statements!E11-Statements!E13,""),"") -> 46022 | F12: =IF(COUNT(Statements!F11,Statements!F13)=2,IF(TRUE,Statements!F11-Statements!F13,""),"") -> 50453 | H12: =IF(Statements!H89,Statements!H11-Statements!H13,"") | I12: =IF(Statements!I89,Statements!I11-Statements!I13,"") | J12: =IF(Statements!J89,Statements!J11-Statements!J13,"") | K12: =IF(Statements!K89,Statements!K11-Statements!K13,"") | L12: =IF(Statements!L89,Statements!L11-Statements!L13,"") | N12: Gross profit less EBITDA. EBITDA itself is set by the margin input.
B13: EBITDA | D13: =IF(COUNT(Statements!D15,Statements!D14)=2,IF(TRUE,Statements!D15+Statements!D14,""),"") -> 125820 | E13: =IF(COUNT(Statements!E15,Statements!E14)=2,IF(TRUE,Statements!E15+Statements!E14,""),"") -> 134661 | F13: =IF(COUNT(Statements!F15,Statements!F14)=2,IF(TRUE,Statements!F15+Statements!F14,""),"") -> 144748 | H13: =IF(Statements!H89,Statements!H9*Assumptions!F11,"") | I13: =IF(Statements!I89,Statements!I9*Assumptions!G11,"") | J13: =IF(Statements!J89,Statements!J9*Assumptions!H11,"") | K13: =IF(Statements!K89,Statements!K9*Assumptions!I11,"") | L13: =IF(Statements!L89,Statements!L9*Assumptions!J11,"")
B14: Depreciation and amortization | D14: =IF(COUNT(History!E13)=1,IF(TRUE,History!E13,""),"") -> 11519 | E14: =IF(COUNT(History!F13)=1,IF(TRUE,History!F13,""),"") -> 11445 | F14: =IF(COUNT(History!G13)=1,IF(TRUE,History!G13,""),"") -> 11698 | H14: =IF(Statements!H89,Statements!F34*Assumptions!F17,"") | I14: =IF(Statements!I89,Statements!H34*Assumptions!G17,"") | J14: =IF(Statements!J89,Statements!I34*Assumptions!H17,"") | K14: =IF(Statements!K89,Statements!J34*Assumptions!I17,"") | L14: =IF(Statements!L89,Statements!K34*Assumptions!J17,"")
B15: Operating profit (EBIT) | D15: =IF(ISNUMBER(History!E14),History!E14,IF(COUNT(History!E12,History!E13)=2,History!E12-History!E13,"")) -> 114301 | E15: =IF(ISNUMBER(History!F14),History!F14,IF(COUNT(History!F12,History!F13)=2,History!F12-History!F13,"")) -> 123216 | F15: =IF(ISNUMBER(History!G14),History!G14,IF(COUNT(History!G12,History!G13)=2,History!G12-History!G13,"")) -> 133050 | H15: =IF(Statements!H89,Statements!H13-Statements!H14,"") | I15: =IF(Statements!I89,Statements!I13-Statements!I14,"") | J15: =IF(Statements!J89,Statements!J13-Statements!J14,"") | K15: =IF(Statements!K89,Statements!K13-Statements!K14,"") | L15: =IF(Statements!L89,Statements!L13-Statements!L14,"")
B16: Net finance and other costs | D16: =IF(COUNT(Statements!D15,Statements!D17)=2,IF(TRUE,Statements!D15-Statements!D17,""),"") -> 565 | E16: =IF(COUNT(Statements!E15,Statements!E17)=2,IF(TRUE,Statements!E15-Statements!E17,""),"") -> -269 | F16: =IF(COUNT(Statements!F15,Statements!F17)=2,IF(TRUE,Statements!F15-Statements!F17,""),"") -> 321 | H16: =IF(Statements!H89,Statements!F39*Assumptions!F18-Assumptions!F22,"") | I16: =IF(Statements!I89,Statements!H39*Assumptions!G18-Assumptions!G22,"") | J16: =IF(Statements!J89,Statements!I39*Assumptions!H18-Assumptions!H22,"") | K16: =IF(Statements!K89,Statements!J39*Assumptions!I18-Assumptions!I22,"") | L16: =IF(Statements!L89,Statements!K39*Assumptions!J18-Assumptions!J22,"") | N16: Actuals: EBIT less reported pre-tax profit. Forecast: interest on opening debt, less entered other income.
B17: Profit before tax | D17: =IF(COUNT(History!E17)=1,IF(TRUE,History!E17,""),"") -> 113736 | E17: =IF(COUNT(History!F17)=1,IF(TRUE,History!F17,""),"") -> 123485 | F17: =IF(COUNT(History!G17)=1,IF(TRUE,History!G17,""),"") -> 132729 | H17: =IF(Statements!H89,Statements!H15-Statements!H16,"") | I17: =IF(Statements!I89,Statements!I15-Statements!I16,"") | J17: =IF(Statements!J89,Statements!J15-Statements!J16,"") | K17: =IF(Statements!K89,Statements!K15-Statements!K16,"") | L17: =IF(Statements!L89,Statements!L15-Statements!L16,"")
B18: Income tax | D18: =IF(COUNT(History!E18)=1,IF(TRUE,History!E18,""),"") -> 16741 | E18: =IF(COUNT(History!F18)=1,IF(TRUE,History!F18,""),"") -> 29749 | F18: =IF(COUNT(History!G18)=1,IF(TRUE,History!G18,""),"") -> 20719 | H18: =IF(Statements!H89,MAX(0,Statements!H17)*Assumptions!F12,"") | I18: =IF(Statements!I89,MAX(0,Statements!I17)*Assumptions!G12,"") | J18: =IF(Statements!J89,MAX(0,Statements!J17)*Assumptions!H12,"") | K18: =IF(Statements!K89,MAX(0,Statements!K17)*Assumptions!I12,"") | L18: =IF(Statements!L89,MAX(0,Statements!L17)*Assumptions!J12,"")
B19: Net profit | D19: =IF(COUNT(History!E19)=1,IF(TRUE,History!E19,""),"") -> 96995 | E19: =IF(COUNT(History!F19)=1,IF(TRUE,History!F19,""),"") -> 93736 | F19: =IF(COUNT(History!G19)=1,IF(TRUE,History!G19,""),"") -> 112010 | H19: =IF(Statements!H89,Statements!H17-Statements!H18,"") | I19: =IF(Statements!I89,Statements!I17-Statements!I18,"") | J19: =IF(Statements!J89,Statements!J17-Statements!J18,"") | K19: =IF(Statements!K89,Statements!K17-Statements!K18,"") | L19: =IF(Statements!L89,Statements!L17-Statements!L18,"")
B29: Balance sheet | C29: Balance sheet | D29: Balance sheet | E29: Balance sheet | F29: Balance sheet | G29: Balance sheet | H29: Balance sheet | I29: Balance sheet | J29: Balance sheet | K29: Balance sheet | L29: Balance sheet
B31: Cash and cash equivalents | D31: =IF(COUNT(History!E21)=1,IF(TRUE,History!E21,""),"") -> 29965 | E31: =IF(COUNT(History!F21)=1,IF(TRUE,History!F21,""),"") -> 29943 | F31: =IF(COUNT(History!G21)=1,IF(TRUE,History!G21,""),"") -> 35934 | H31: =IF(Statements!H89,Statements!H73,"") | I31: =IF(Statements!I89,Statements!I73,"") | J31: =IF(Statements!J89,Statements!J73,"") | K31: =IF(Statements!K89,Statements!K73,"") | L31: =IF(Statements!L89,Statements!L73,"")
B32: Trade receivables | D32: =IF(COUNT(History!E22)=1,IF(TRUE,History!E22,""),"") -> 29508 | E32: =IF(COUNT(History!F22)=1,IF(TRUE,History!F22,""),"") -> 33410 | F32: =IF(COUNT(History!G22)=1,IF(TRUE,History!G22,""),"") -> 39777 | H32: =IF(Statements!H89,Statements!H9/365*Assumptions!F13,"") | I32: =IF(Statements!I89,Statements!I9/365*Assumptions!G13,"") | J32: =IF(Statements!J89,Statements!J9/365*Assumptions!H13,"") | K32: =IF(Statements!K89,Statements!K9/365*Assumptions!I13,"") | L32: =IF(Statements!L89,Statements!L9/365*Assumptions!J13,"")
B33: Inventory | D33: =IF(COUNT(History!E23)=1,IF(TRUE,History!E23,""),"") -> 6331 | E33: =IF(COUNT(History!F23)=1,IF(TRUE,History!F23,""),"") -> 7286 | F33: =IF(COUNT(History!G23)=1,IF(TRUE,History!G23,""),"") -> 5718 | H33: =IF(Statements!H89,Statements!H10/365*Assumptions!F14,"") | I33: =IF(Statements!I89,Statements!I10/365*Assumptions!G14,"") | J33: =IF(Statements!J89,Statements!J10/365*Assumptions!H14,"") | K33: =IF(Statements!K89,Statements!K10/365*Assumptions!I14,"") | L33: =IF(Statements!L89,Statements!L10/365*Assumptions!J14,"")
B34: Net fixed assets | D34: =IF(COUNT(History!E24)=1,IF(TRUE,History!E24,""),"") -> 43715 | E34: =IF(COUNT(History!F24)=1,IF(TRUE,History!F24,""),"") -> 45680 | F34: =IF(COUNT(History!G24)=1,IF(TRUE,History!G24,""),"") -> 49834 | H34: =IF(Statements!H89,Statements!F34+Statements!H63-Statements!H14,"") | I34: =IF(Statements!I89,Statements!H34+Statements!I63-Statements!I14,"") | J34: =IF(Statements!J89,Statements!I34+Statements!J63-Statements!J14,"") | K34: =IF(Statements!K89,Statements!J34+Statements!K63-Statements!K14,"") | L34: =IF(Statements!L89,Statements!K34+Statements!L63-Statements!L14,"")
B35: Other assets (derived) | D35: =IF(COUNT(Statements!D36,Statements!D31,Statements!D32,Statements!D33,Statements!D34)=5,IF(TRUE,Statements!D36-SUM(Statements!D31:'Statements'!D34),""),"") -> 243064 | E35: =IF(COUNT(Statements!E36,Statements!E31,Statements!E32,Statements!E33,Statements!E34)=5,IF(TRUE,Statements!E36-SUM(Statements!E31:'Statements'!E34),""),"") -> 248661 | F35: =IF(COUNT(Statements!F36,Statements!F31,Statements!F32,Statements!F33,Statements!F34)=5,IF(TRUE,Statements!F36-SUM(Statements!F31:'Statements'!F34),""),"") -> 227978 | H35: =IF(Statements!H89,Statements!F35,"") | I35: =IF(Statements!I89,Statements!H35,"") | J35: =IF(Statements!J89,Statements!I35,"") | K35: =IF(Statements!K89,Statements!J35,"") | L35: =IF(Statements!L89,Statements!K35,"") | N35: Total assets less cash, receivables, inventory and fixed assets. This remainder stays constant in the forecast.
B36: Total assets | D36: =IF(COUNT(History!E25)=1,IF(TRUE,History!E25,""),"") -> 352583 | E36: =IF(COUNT(History!F25)=1,IF(TRUE,History!F25,""),"") -> 364980 | F36: =IF(COUNT(History!G25)=1,IF(TRUE,History!G25,""),"") -> 359241 | H36: =IF(Statements!H89,SUM(Statements!H31:'Statements'!H35),"") | I36: =IF(Statements!I89,SUM(Statements!I31:'Statements'!I35),"") | J36: =IF(Statements!J89,SUM(Statements!J31:'Statements'!J35),"") | K36: =IF(Statements!K89,SUM(Statements!K31:'Statements'!K35),"") | L36: =IF(Statements!L89,SUM(Statements!L31:'Statements'!L35),"")
B38: Trade payables | D38: =IF(COUNT(History!E26)=1,IF(TRUE,History!E26,""),"") -> 62611 | E38: =IF(COUNT(History!F26)=1,IF(TRUE,History!F26,""),"") -> 68960 | F38: =IF(COUNT(History!G26)=1,IF(TRUE,History!G26,""),"") -> 69860 | H38: =IF(Statements!H89,Statements!H10/365*Assumptions!F15,"") | I38: =IF(Statements!I89,Statements!I10/365*Assumptions!G15,"") | J38: =IF(Statements!J89,Statements!J10/365*Assumptions!H15,"") | K38: =IF(Statements!K89,Statements!K10/365*Assumptions!I15,"") | L38: =IF(Statements!L89,Statements!L10/365*Assumptions!J15,"")
B39: Total debt | D39: =IF(COUNT(History!E27)=1,IF(TRUE,History!E27,""),"") -> 111088 | E39: =IF(COUNT(History!F27)=1,IF(TRUE,History!F27,""),"") -> 106629 | F39: =IF(COUNT(History!G27)=1,IF(TRUE,History!G27,""),"") -> 98657 | H39: =IF(Statements!H89,Statements!F39+Assumptions!F20-Statements!F39*Assumptions!F19,"") | I39: =IF(Statements!I89,Statements!H39+Assumptions!G20-Statements!H39*Assumptions!G19,"") | J39: =IF(Statements!J89,Statements!I39+Assumptions!H20-Statements!I39*Assumptions!H19,"") | K39: =IF(Statements!K89,Statements!J39+Assumptions!I20-Statements!J39*Assumptions!I19,"") | L39: =IF(Statements!L89,Statements!K39+Assumptions!J20-Statements!K39*Assumptions!J19,"")
B40: Other liabilities (derived) | D40: =IF(COUNT(Statements!D41,Statements!D38,Statements!D39)=3,IF(TRUE,Statements!D41-Statements!D38-Statements!D39,""),"") -> 116738 | E40: =IF(COUNT(Statements!E41,Statements!E38,Statements!E39)=3,IF(TRUE,Statements!E41-Statements!E38-Statements!E39,""),"") -> 132441 | F40: =IF(COUNT(Statements!F41,Statements!F38,Statements!F39)=3,IF(TRUE,Statements!F41-Statements!F38-Statements!F39,""),"") -> 116991 | H40: =IF(Statements!H89,Statements!F40,"") | I40: =IF(Statements!I89,Statements!H40,"") | J40: =IF(Statements!J89,Statements!I40,"") | K40: =IF(Statements!K89,Statements!J40,"") | L40: =IF(Statements!L89,Statements!K40,"") | N40: Total liabilities less trade payables and debt. This remainder stays constant in the forecast.
B41: Total liabilities | D41: =IF(ISNUMBER(History!E28),History!E28,IF(COUNT(History!E27,History!E50)=2,History!E27+History!E50,"")) -> 290437 | E41: =IF(ISNUMBER(History!F28),History!F28,IF(COUNT(History!F27,History!F50)=2,History!F27+History!F50,"")) -> 308030 | F41: =IF(ISNUMBER(History!G28),History!G28,IF(COUNT(History!G27,History!G50)=2,History!G27+History!G50,"")) -> 285508 | H41: =IF(Statements!H89,SUM(Statements!H38:'Statements'!H40),"") | I41: =IF(Statements!I89,SUM(Statements!I38:'Statements'!I40),"") | J41: =IF(Statements!J89,SUM(Statements!J38:'Statements'!J40),"") | K41: =IF(Statements!K89,SUM(Statements!K38:'Statements'!K40),"") | L41: =IF(Statements!L89,SUM(Statements!L38:'Statements'!L40),"")
B42: Total equity | D42: =IF(ISNUMBER(History!E29),History!E29,IF(COUNT(History!E47,History!E48)=2,History!E47+History!E48,"")) -> 62146 | E42: =IF(ISNUMBER(History!F29),History!F29,IF(COUNT(History!F47,History!F48)=2,History!F47+History!F48,"")) -> 56950 | F42: =IF(ISNUMBER(History!G29),History!G29,IF(COUNT(History!G47,History!G48)=2,History!G47+History!G48,"")) -> 73733 | H42: =IF(Statements!H89,Statements!F42+Statements!H19-Statements!H67+Assumptions!F23,"") | I42: =IF(Statements!I89,Statements!H42+Statements!I19-Statements!I67+Assumptions!G23,"") | J42: =IF(Statements!J89,Statements!I42+Statements!J19-Statements!J67+Assumptions!H23,"") | K42: =IF(Statements!K89,Statements!J42+Statements!K19-Statements!K67+Assumptions!I23,"") | L42: =IF(Statements!L89,Statements!K42+Statements!L19-Statements!L67+Assumptions!J23,"") | N42: Previous equity + net profit - dividends + net cash from shares issued or repurchased.
B43: Liabilities and equity | D43: =IF(COUNT(Statements!D41,Statements!D42)=2,IF(TRUE,Statements!D41+Statements!D42,""),"") -> 352583 | E43: =IF(COUNT(Statements!E41,Statements!E42)=2,IF(TRUE,Statements!E41+Statements!E42,""),"") -> 364980 | F43: =IF(COUNT(Statements!F41,Statements!F42)=2,IF(TRUE,Statements!F41+Statements!F42,""),"") -> 359241 | H43: =IF(Statements!H89,Statements!H41+Statements!H42,"") | I43: =IF(Statements!I89,Statements!I41+Statements!I42,"") | J43: =IF(Statements!J89,Statements!J41+Statements!J42,"") | K43: =IF(Statements!K89,Statements!K41+Statements!K42,"") | L43: =IF(Statements!L89,Statements!L41+Statements!L42,"")
B55: Cash flow statement | C55: Cash flow statement | D55: Cash flow statement | E55: Cash flow statement | F55: Cash flow statement | G55: Cash flow statement | H55: Cash flow statement | I55: Cash flow statement | J55: Cash flow statement | K55: Cash flow statement | L55: Cash flow statement
B58: Net profit | D58: =IF(COUNT(Statements!D19)=1,IF(TRUE,Statements!D19,""),"") -> 96995 | E58: =IF(COUNT(Statements!E19)=1,IF(TRUE,Statements!E19,""),"") -> 93736 | F58: =IF(COUNT(Statements!F19)=1,IF(TRUE,Statements!F19,""),"") -> 112010 | H58: =IF(Statements!H89,Statements!H19,"") | I58: =IF(Statements!I89,Statements!I19,"") | J58: =IF(Statements!J89,Statements!J19,"") | K58: =IF(Statements!K89,Statements!K19,"") | L58: =IF(Statements!L89,Statements!L19,"")
B59: Depreciation added back | D59: =IF(COUNT(Statements!D14)=1,IF(TRUE,Statements!D14,""),"") -> 11519 | E59: =IF(COUNT(Statements!E14)=1,IF(TRUE,Statements!E14,""),"") -> 11445 | F59: =IF(COUNT(Statements!F14)=1,IF(TRUE,Statements!F14,""),"") -> 11698 | H59: =IF(Statements!H89,Statements!H14,"") | I59: =IF(Statements!I89,Statements!I14,"") | J59: =IF(Statements!J89,Statements!J14,"") | K59: =IF(Statements!K89,Statements!K14,"") | L59: =IF(Statements!L89,Statements!L14,"")
B60: Other operating cash adjustments | D60: =IF(COUNT(Statements!D62,Statements!D58,Statements!D59,Statements!D61)=4,IF(TRUE,Statements!D62-Statements!D58-Statements!D59+Statements!D61,""),"") -> 6242 | E60: =IF(COUNT(Statements!E62,Statements!E58,Statements!E59,Statements!E61)=4,IF(TRUE,Statements!E62-Statements!E58-Statements!E59+Statements!E61,""),"") -> 11581 | F60: =IF(COUNT(Statements!F62,Statements!F58,Statements!F59,Statements!F61)=4,IF(TRUE,Statements!F62-Statements!F58-Statements!F59+Statements!F61,""),"") -> -8327 | H60: =IF(Statements!H89,0,"") | I60: =IF(Statements!I89,0,"") | J60: =IF(Statements!J89,0,"") | K60: =IF(Statements!K89,0,"") | L60: =IF(Statements!L89,0,"") | N60: Actuals reconcile reported operating cash. No additional noncash adjustments are forecast.
B61: Increase in working capital | D61: =IF(COUNT(History!E22,History!E23,History!E26,History!D22,History!D23,History!D26)=6,IF(TRUE,Statements!D86-(History!D22+History!D23-History!D26),""),"") -> 4213 | E61: =IF(COUNT(History!F22,History!F23,History!F26,History!E22,History!E23,History!E26)=6,IF(TRUE,Statements!E86-(History!E22+History!E23-History!E26),""),"") -> -1492 | F61: =IF(COUNT(History!G22,History!G23,History!G26,History!F22,History!F23,History!F26)=6,IF(TRUE,Statements!F86-(History!F22+History!F23-History!F26),""),"") -> 3899 | H61: =IF(Statements!H89,Statements!H86-Statements!F86,"") | I61: =IF(Statements!I89,Statements!I86-Statements!H86,"") | J61: =IF(Statements!J89,Statements!J86-Statements!I86,"") | K61: =IF(Statements!K89,Statements!K86-Statements!J86,"") | L61: =IF(Statements!L89,Statements!L86-Statements!K86,"")
B62: Cash from operations | D62: =IF(COUNT(History!E33)=1,IF(TRUE,History!E33,""),"") -> 110543 | E62: =IF(COUNT(History!F33)=1,IF(TRUE,History!F33,""),"") -> 118254 | F62: =IF(COUNT(History!G33)=1,IF(TRUE,History!G33,""),"") -> 111482 | H62: =IF(Statements!H89,Statements!H58+Statements!H59-Statements!H61,"") | I62: =IF(Statements!I89,Statements!I58+Statements!I59-Statements!I61,"") | J62: =IF(Statements!J89,Statements!J58+Statements!J59-Statements!J61,"") | K62: =IF(Statements!K89,Statements!K58+Statements!K59-Statements!K61,"") | L62: =IF(Statements!L89,Statements!L58+Statements!L59-Statements!L61,"")
B63: Capital spending (outflow) | D63: =IF(COUNT(History!E36)=1,IF(TRUE,History!E36,""),"") -> 10959 | E63: =IF(COUNT(History!F36)=1,IF(TRUE,History!F36,""),"") -> 9447 | F63: =IF(COUNT(History!G36)=1,IF(TRUE,History!G36,""),"") -> 12715 | H63: =IF(Statements!H89,Statements!H9*Assumptions!F16,"") | I63: =IF(Statements!I89,Statements!I9*Assumptions!G16,"") | J63: =IF(Statements!J89,Statements!J9*Assumptions!H16,"") | K63: =IF(Statements!K89,Statements!K9*Assumptions!I16,"") | L63: =IF(Statements!L89,Statements!L9*Assumptions!J16,"")
B64: Other investing cash flow | D64: =IF(COUNT(Statements!D65,Statements!D63)=2,IF(TRUE,Statements!D65+Statements!D63,""),"") -> 14664 | E64: =IF(COUNT(Statements!E65,Statements!E63)=2,IF(TRUE,Statements!E65+Statements!E63,""),"") -> 12382 | F64: =IF(COUNT(Statements!F65,Statements!F63)=2,IF(TRUE,Statements!F65+Statements!F63,""),"") -> 27910 | H64: =IF(Statements!H89,0,"") | I64: =IF(Statements!I89,0,"") | J64: =IF(Statements!J89,0,"") | K64: =IF(Statements!K89,0,"") | L64: =IF(Statements!L89,0,"") | N64: Actuals: investing cash flow plus capital spending. No other investing cash flows are forecast.
B65: Cash from investing | D65: =IF(COUNT(History!E34)=1,IF(TRUE,History!E34,""),"") -> 3705 | E65: =IF(COUNT(History!F34)=1,IF(TRUE,History!F34,""),"") -> 2935 | F65: =IF(COUNT(History!G34)=1,IF(TRUE,History!G34,""),"") -> 15195 | H65: =IF(Statements!H89,-Statements!H63,"") | I65: =IF(Statements!I89,-Statements!I63,"") | J65: =IF(Statements!J89,-Statements!J63,"") | K65: =IF(Statements!K89,-Statements!K63,"") | L65: =IF(Statements!L89,-Statements!L63,"")
B66: Net borrowing / (repayment) | D66: =IF(COUNT(History!E42)=1,IF(TRUE,History!E42,""),"") -> -9901 | E66: =IF(COUNT(History!F42)=1,IF(TRUE,History!F42,""),"") -> -5998 | F66: =IF(COUNT(History!G42)=1,IF(TRUE,History!G42,""),"") -> -8483 | H66: =IF(Statements!H89,Assumptions!F20-Statements!F39*Assumptions!F19,"") | I66: =IF(Statements!I89,Assumptions!G20-Statements!H39*Assumptions!G19,"") | J66: =IF(Statements!J89,Assumptions!H20-Statements!I39*Assumptions!H19,"") | K66: =IF(Statements!K89,Assumptions!I20-Statements!J39*Assumptions!I19,"") | L66: =IF(Statements!L89,Assumptions!J20-Statements!K39*Assumptions!J19,"") | N66: Actual debt cash movements are not inferred from changes in the balance sheet.
B67: Dividends paid (outflow) | D67: =IF(COUNT(History!E37)=1,IF(TRUE,History!E37,""),"") -> 15025 | E67: =IF(COUNT(History!F37)=1,IF(TRUE,History!F37,""),"") -> 15234 | F67: =IF(COUNT(History!G37)=1,IF(TRUE,History!G37,""),"") -> 15421 | H67: =IF(Statements!H89,MAX(0,Statements!H19)*Assumptions!F21,"") | I67: =IF(Statements!I89,MAX(0,Statements!I19)*Assumptions!G21,"") | J67: =IF(Statements!J89,MAX(0,Statements!J19)*Assumptions!H21,"") | K67: =IF(Statements!K89,MAX(0,Statements!K19)*Assumptions!I21,"") | L67: =IF(Statements!L89,MAX(0,Statements!L19)*Assumptions!J21,"")
...

Sheet DCF
B2: Apple Inc. — DCF
B3: USD millions. Shares in millions. Per-share values in USD. Latest source period: 2025-09-30.
B4: Finish the forecast first, then enter the DCF inputs on Assumptions. Cash flows are discounted at each year end. A missing value stays blank; it does not mean zero.
B6: Next step | D6: =IF(ISNUMBER(D40),"Review the result and model checks",IF(COUNT(Assumptions!F31,Assumptions!F32)<2,"Enter discount rate and long-run growth",IF(Assumptions!F31<=0,"Discount rate must be positive",IF(OR(Assumptions!F32<=-1,Assumptions!F32>=Assumptions!F31),"Long-run growth must be below WACC",IF(COUNT(D15:H15)<5,"Complete the forecast on Assumptions","Enter shares, claims and non-operating assets"))))) -> Enter discount rate and long-run growth
D7: 2026 | E7: 2027 | F7: 2028 | G7: 2029 | H7: 2030
B9: Operating profit (EBIT) | D9: =IF(COUNT(Statements!H15)=1,IF(TRUE,Statements!H15,""),"") | E9: =IF(COUNT(Statements!I15)=1,IF(TRUE,Statements!I15,""),"") | F9: =IF(COUNT(Statements!J15)=1,IF(TRUE,Statements!J15,""),"") | G9: =IF(COUNT(Statements!K15)=1,IF(TRUE,Statements!K15,""),"") | H9: =IF(COUNT(Statements!L15)=1,IF(TRUE,Statements!L15,""),"")
B10: Tax on operating profit | D10: =IF(COUNT(DCF!D9,Assumptions!F12)=2,IF(AND(Assumptions!F12>=0,Assumptions!F12<=1),MAX(0,DCF!D9)*Assumptions!F12,""),"") | E10: =IF(COUNT(DCF!E9,Assumptions!G12)=2,IF(AND(Assumptions!G12>=0,Assumptions!G12<=1),MAX(0,DCF!E9)*Assumptions!G12,""),"") | F10: =IF(COUNT(DCF!F9,Assumptions!H12)=2,IF(AND(Assumptions!H12>=0,Assumptions!H12<=1),MAX(0,DCF!F9)*Assumptions!H12,""),"") | G10: =IF(COUNT(DCF!G9,Assumptions!I12)=2,IF(AND(Assumptions!I12>=0,Assumptions!I12<=1),MAX(0,DCF!G9)*Assumptions!I12,""),"") | H10: =IF(COUNT(DCF!H9,Assumptions!J12)=2,IF(AND(Assumptions!J12>=0,Assumptions!J12<=1),MAX(0,DCF!H9)*Assumptions!J12,""),"")
B11: Operating profit after tax | D11: =IF(COUNT(DCF!D9,DCF!D10)=2,IF(TRUE,DCF!D9-DCF!D10,""),"") | E11: =IF(COUNT(DCF!E9,DCF!E10)=2,IF(TRUE,DCF!E9-DCF!E10,""),"") | F11: =IF(COUNT(DCF!F9,DCF!F10)=2,IF(TRUE,DCF!F9-DCF!F10,""),"") | G11: =IF(COUNT(DCF!G9,DCF!G10)=2,IF(TRUE,DCF!G9-DCF!G10,""),"") | H11: =IF(COUNT(DCF!H9,DCF!H10)=2,IF(TRUE,DCF!H9-DCF!H10,""),"")
B12: Depreciation added back | D12: =IF(COUNT(Statements!H14)=1,IF(TRUE,Statements!H14,""),"") | E12: =IF(COUNT(Statements!I14)=1,IF(TRUE,Statements!I14,""),"") | F12: =IF(COUNT(Statements!J14)=1,IF(TRUE,Statements!J14,""),"") | G12: =IF(COUNT(Statements!K14)=1,IF(TRUE,Statements!K14,""),"") | H12: =IF(COUNT(Statements!L14)=1,IF(TRUE,Statements!L14,""),"")
B13: Capital spending (outflow) | D13: =IF(COUNT(Statements!H63)=1,IF(TRUE,Statements!H63,""),"") | E13: =IF(COUNT(Statements!I63)=1,IF(TRUE,Statements!I63,""),"") | F13: =IF(COUNT(Statements!J63)=1,IF(TRUE,Statements!J63,""),"") | G13: =IF(COUNT(Statements!K63)=1,IF(TRUE,Statements!K63,""),"") | H13: =IF(COUNT(Statements!L63)=1,IF(TRUE,Statements!L63,""),"")
B14: Increase in working capital | D14: =IF(COUNT(Statements!H61)=1,IF(TRUE,Statements!H61,""),"") | E14: =IF(COUNT(Statements!I61)=1,IF(TRUE,Statements!I61,""),"") | F14: =IF(COUNT(Statements!J61)=1,IF(TRUE,Statements!J61,""),"") | G14: =IF(COUNT(Statements!K61)=1,IF(TRUE,Statements!K61,""),"") | H14: =IF(COUNT(Statements!L61)=1,IF(TRUE,Statements!L61,""),"")
B15: Free cash flow to the firm | D15: =IF(COUNT(DCF!D11,DCF!D12,DCF!D13,DCF!D14)=4,IF(TRUE,DCF!D11+DCF!D12-DCF!D13-DCF!D14,""),"") | E15: =IF(COUNT(DCF!E11,DCF!E12,DCF!E13,DCF!E14)=4,IF(TRUE,DCF!E11+DCF!E12-DCF!E13-DCF!E14,""),"") | F15: =IF(COUNT(DCF!F11,DCF!F12,DCF!F13,DCF!F14)=4,IF(TRUE,DCF!F11+DCF!F12-DCF!F13-DCF!F14,""),"") | G15: =IF(COUNT(DCF!G11,DCF!G12,DCF!G13,DCF!G14)=4,IF(TRUE,DCF!G11+DCF!G12-DCF!G13-DCF!G14,""),"") | H15: =IF(COUNT(DCF!H11,DCF!H12,DCF!H13,DCF!H14)=4,IF(TRUE,DCF!H11+DCF!H12-DCF!H13-DCF!H14,""),"")
B18: Year-end discount factor | D18: =IF(COUNT(Assumptions!F31)=1,IF(Assumptions!F31>0,1/(1+Assumptions!F31)^1,""),"") | E18: =IF(COUNT(Assumptions!F31)=1,IF(Assumptions!F31>0,1/(1+Assumptions!F31)^2,""),"") | F18: =IF(COUNT(Assumptions!F31)=1,IF(Assumptions!F31>0,1/(1+Assumptions!F31)^3,""),"") | G18: =IF(COUNT(Assumptions!F31)=1,IF(Assumptions!F31>0,1/(1+Assumptions!F31)^4,""),"") | H18: =IF(COUNT(Assumptions!F31)=1,IF(Assumptions!F31>0,1/(1+Assumptions!F31)^5,""),"")
B19: Present value of cash flow | D19: =IF(COUNT(DCF!D15,DCF!D18)=2,IF(TRUE,DCF!D15*DCF!D18,""),"") | E19: =IF(COUNT(DCF!E15,DCF!E18)=2,IF(TRUE,DCF!E15*DCF!E18,""),"") | F19: =IF(COUNT(DCF!F15,DCF!F18)=2,IF(TRUE,DCF!F15*DCF!F18,""),"") | G19: =IF(COUNT(DCF!G15,DCF!G18)=2,IF(TRUE,DCF!G15*DCF!G18,""),"") | H19: =IF(COUNT(DCF!H15,DCF!H18)=2,IF(TRUE,DCF!H15*DCF!H18,""),"")
B21: Value after year five | C21: Value after year five | D21: Value after year five | E21: Value after year five | F21: Value after year five | G21: Value after year five | H21: Value after year five
B23: Year-six cash flow | D23: =IF(COUNT(H15,Assumptions!F32)=2,IF(Assumptions!F32>-1,H15*(1+Assumptions!F32),""),"") | J23: Year-five cash flow × (1 + long-run growth). Check that future investment supports this growth.
B24: Terminal value at year five | D24: =IF(COUNT(DCF!D23,Assumptions!F31,Assumptions!F32)=3,IF(AND(Assumptions!F31>0,Assumptions!F32>-1,Assumptions!F32<Assumptions!F31),DCF!D23/(Assumptions!F31-Assumptions!F32),""),"") | J24: Year-six cash flow / (WACC - long-run growth). The growth rate must stay below WACC.
B25: Present value of terminal value | D25: =IF(COUNT(DCF!D24,H18)=2,IF(TRUE,DCF!D24*H18,""),"")
B27: From business value to value per share | C27: From business value to value per share | D27: From business value to value per share | E27: From business value to value per share | F27: From business value to value per share | G27: From business value to value per share | H27: From business value to value per share
B29: Present value of five-year cash flows | D29: =IF(COUNT(D19,E19,F19,G19,H19)=5,IF(TRUE,SUM(D19:H19),""),"")
B30: Present value of terminal value | D30: =IF(COUNT(DCF!D25)=1,IF(TRUE,DCF!D25,""),"")
B31: Operating business value | D31: =IF(COUNT(DCF!D29,DCF!D30)=2,IF(TRUE,DCF!D29+DCF!D30,""),"")
B33: Cash to add | D33: =IF(COUNT(Statements!F31)=1,IF(TRUE,Statements!F31,""),"") -> 35934
B34: Debt to deduct | D34: =IF(COUNT(Statements!F39)=1,IF(Statements!F39>=0,Statements!F39,""),"") -> 98657
B35: Other claims to deduct | D35: =IF(COUNT(Assumptions!F34)=1,IF(Assumptions!F34>=0,Assumptions!F34,""),"")
B36: Other non-operating assets to add | D36: =IF(COUNT(Assumptions!F35)=1,IF(Assumptions!F35>=0,Assumptions!F35,""),"")
B37: Equity value | D37: =IF(COUNT(DCF!D31,DCF!D33,DCF!D34,DCF!D35,DCF!D36)=5,IF(TRUE,DCF!D31+DCF!D33-DCF!D34-DCF!D35+DCF!D36,""),"") | J37: Operating value + cash - debt - other claims + eligible non-operating assets.
B39: Shares outstanding (millions) | D39: =IF(COUNT(Assumptions!F33)=1,IF(Assumptions!F33>0,Assumptions!F33,""),"")
B40: Value per share | D40: =IF(COUNT(DCF!D37,DCF!D39)=2,IF(DCF!D39>0,DCF!D37*1000000/(DCF!D39*1000000),""),"")
B42: Current share price (optional) | D42: =IF(COUNT(Assumptions!F36)=1,IF(Assumptions!F36>0,Assumptions!F36,""),"")
B43: Upside / downside (optional) | D43: =IF(COUNT(DCF!D40,DCF!D42)=2,IF(DCF!D42>0,DCF!D40/DCF!D42-1,""),"")
B47: A negative cash flow or valuation is shown as calculated. Review whether the business and terminal-year assumptions are appropriate. The tax model gives no immediate credit for operating losses; it does not project tax-loss carryforwards.
B51: Method reference: https://www.cfainstitute.org/insights/professional-learning/refresher-readings/2026/free-cash-flow-valuation

Sheet History
B2: Apple Inc. — History
B3: USD millions. Latest source period: 2025-09-30.
B4: All available annual history is here. Green numbers came from the saved source. Yellow blanks are missing. Correct a figure here only after checking the original statements. Raw statements and downloaded files remain unchanged.
B7: Reported item | C7: Source field | D7: 2022-09-30 | E7: 2023-09-30 | F7: 2024-09-30 | G7: 2025-09-30
B9: Revenue | C9: revenue | D9: 394328 | E9: 383285 | F9: 391035 | G9: 416161
B10: Cost of sales | C10: cogs | D10: 223546 | E10: 214137 | F10: 210352 | G10: 220960
B11: Gross profit | C11: gross_profit | D11: 170782 | E11: 169148 | F11: 180683 | G11: 195201
B12: EBITDA (provider definition) | C12: ebitda | D12: 130541 | E12: 125820 | F12: 134661 | G12: 144748
B13: Depreciation & amortization | C13: da | D13: 11104 | E13: 11519 | F13: 11445 | G13: 11698
B14: Operating profit (EBIT) | C14: ebit | D14: 119437 | E14: 114301 | F14: 123216 | G14: 133050
B15: Interest expense | C15: interest | D15: 2931 | E15: 3933
B16: Other non-operating income | C16: other_income | D16: -334 | E16: -565 | F16: 269 | G16: -321
B17: Profit before tax | C17: pbt | D17: 119103 | E17: 113736 | F17: 123485 | G17: 132729
B18: Income tax expense | C18: tax | D18: 19300 | E18: 16741 | F18: 29749 | G18: 20719
B19: Net profit (reported basis) | C19: net_profit | D19: 99803 | E19: 96995 | F19: 93736 | G19: 112010
B20: Net profit attributable to parent | C20: parent_profit | D20: 99803 | E20: 96995 | F20: 93736 | G20: 112010
B21: Cash & cash equivalents | C21: cash | D21: 23646 | E21: 29965 | F21: 29943 | G21: 35934
B22: Trade receivables | C22: receivables | D22: 28184 | E22: 29508 | F22: 33410 | G22: 39777
B23: Inventories | C23: inventory | D23: 4946 | E23: 6331 | F23: 7286 | G23: 5718
B24: Net property, plant & equipment | C24: ppe | D24: 42117 | E24: 43715 | F24: 45680 | G24: 49834
B25: Total assets | C25: assets | D25: 352755 | E25: 352583 | F25: 364980 | G25: 359241
B26: Trade payables | C26: payables | D26: 64115 | E26: 62611 | F26: 68960 | G26: 69860
B27: Borrowings | C27: debt | D27: 132480 | E27: 111088 | F27: 106629 | G27: 98657
... B30: Parent equity | C30: parent_equity | D30: 50672 | E30: 62146 | F30: 56950 | G30: 73733
B31: Minority equity | C31: minorities
B32: Retained earnings | C32: retained_earnings | D32: -3068 | E32: -214 | F32: -19154 | G32: -14264
B33: Cash from operating activities | C33: cfo | D33: 122151 | E33: 110543 | F33: 118254 | G33: 111482
B34: Cash from investing activities | C34: cfi | D34: -22354 | E34: 3705 | F34: 2935 | G34: 15195
B35: Cash from financing activities | C35: cff | D35: -110749 | E35: -108488 | F35: -121983 | G35: -120686
B36: Cash purchases of PPE | C36: capex | D36: 10708 | E36: 10959 | F36: 9447 | G36: 12715
B37: Cash dividends paid | C37: dividends | D37: 14841 | E37: 15025 | F37: 15234 | G37: 15421
B38: FX effect on cash | C38: fx
B39: Reported change in cash | C39: cash_change | D39: -10952 | E39: 5760 | F39: -794 | G39: 5991
B40: Cash flow opening cash | C40: cash_begin | D40: 35929 | E40: 24977 | F40: 30737 | G40: 29943
B41: Cash flow closing cash | C41: cash_end | D41: 24977 | E41: 30737 | F41: 29943 | G41: 35934
B42: Net debt cash flow | C42: net_borrowing | D42: -123 | E42: -9901 | F42: -5998 | G42: -8483
B43: Cash debt issued | C43: debt_issued | D43: 5465 | E43: 5228 | F43: 0 | G43: 4481
B44: Cash debt repaid | C44: debt_repaid | D44: 9543 | E44: 11151 | F44: 9958 | G44: 10932
B45: Net common shares issued / (repurchased) | C45: net_equity_cash_flow | D45: -89402 | E45: -77550 | F45: -94949 | G45: -90711
B46: Ordinary shares outstanding (millions) | C46: shares | D46: 15943.425 | E46: 15550.061 | F46: 15116.786 | G46: 14773.26
...

Sheet Raw statements
B2: Apple Inc. — Raw statements
B3: Original source units. Latest source period: 2025-09-30.
B4: Original provider values, before unit conversion or mapping. These may use currency units rather than the millions/crores in the model. The downloaded JSON or imported export is also saved with this workbook.
B7: Reported income statement | C7: Reported income statement | D7: Reported income statement | E7: Reported income statement | F7: Reported income statement | G7: Reported income statement | H7: Reported income statement
B9: Original provider field | D9: 2022-09-30 | E9: 2023-09-30 | F9: 2024-09-30 | G9: 2025-09-30
B10: BasicAverageShares | D10: 16215963000 | E10: 15744231000 | F10: 15343783000 | G10: 14948500000
B11: BasicEPS | D11: 6.15 | E11: 6.16 | F11: 6.11 | G11: 7.49
B12: CostOfRevenue | D12: 223546000000 | E12: 214137000000 | F12: 210352000000 | G12: 220960000000
B13: DilutedAverageShares | D13: 16325819000 | E13: 15812547000 | F13: 15408095000 | G13: 15004697000
B14: DilutedEPS | D14: 6.11 | E14: 6.13 | F14: 6.08 | G14: 7.46
B15: DilutedNIAvailtoComStockholders | D15: 99803000000 | E15: 96995000000 | F15: 93736000000 | G15: 112010000000
B16: EBIT | D16: 119437000000 | E16: 114301000000 | F16: 123216000000 | G16: 133050000000
B17: EBITDA | D17: 130541000000 | E17: 125820000000 | F17: 134661000000 | G17: 144748000000
B18: GrossProfit | D18: 170782000000 | E18: 169148000000 | F18: 180683000000 | G18: 195201000000
B19: InterestExpense | D19: 2931000000 | E19: 3933000000
B20: InterestExpenseNonOperating | D20: 2931000000 | E20: 3933000000
B21: InterestIncome | D21: 2825000000 | E21: 3750000000
B22: InterestIncomeNonOperating | D22: 2825000000 | E22: 3750000000
B23: NetIncome | D23: 99803000000 | E23: 96995000000 | F23: 93736000000 | G23: 112010000000
B24: NetIncomeCommonStockholders | D24: 99803000000 | E24: 96995000000 | F24: 93736000000 | G24: 112010000000
B25: NetIncomeContinuousOperations | D25: 99803000000 | E25: 96995000000 | F25: 93736000000 | G25: 112010000000
B26: NetIncomeFromContinuingAndDiscontinuedOperation | D26: 99803000000 | E26: 96995000000 | F26: 93736000000 | G26: 112010000000
B27: NetIncomeFromContinuingOperationNetMinorityInterest | D27: 99803000000 | E27: 96995000000 | F27: 93736000000 | G27: 112010000000
B28: NetIncomeIncludingNoncontrollingInterests | D28: 99803000000 | E28: 96995000000 | F28: 93736000000 | G28: 112010000000
B29: NetInterestIncome | D29: -106000000 | E29: -183000000
B30: NetNonOperatingInterestIncomeExpense | D30: -106000000 | E30: -183000000
B31: NormalizedEBITDA | D31: 130541000000 | E31: 125820000000 | F31: 134661000000 | G31: 144748000000
B32: NormalizedIncome | D32: 99803000000 | E32: 96995000000 | F32: 93736000000 | G32: 112010000000
B33: OperatingExpense | D33: 51345000000 | E33: 54847000000 | F33: 57467000000 | G33: 62151000000
B34: OperatingIncome | D34: 119437000000 | E34: 114301000000 | F34: 123216000000 | G34: 133050000000
B35: OperatingRevenue | D35: 394328000000 | E35: 383285000000 | F35: 391035000000 | G35: 416161000000
B36: OtherIncomeExpense | D36: -334000000 | E36: -565000000 | F36: 269000000 | G36: -321000000
B37: OtherNonOperatingIncomeExpenses | D37: -334000000 | E37: -565000000 | F37: 269000000 | G37: -321000000
B38: PretaxIncome | D38: 119103000000 | E38: 113736000000 | F38: 123485000000 | G38: 132729000000
B39: ReconciledCostOfRevenue | D39: 223546000000 | E39: 214137000000 | F39: 210352000000 | G39: 220960000000
B40: ReconciledDepreciation | D40: 11104000000 | E40: 11519000000 | F40: 11445000000 | G40: 11698000000
B41: ResearchAndDevelopment | D41: 26251000000 | E41: 29915000000 | F41: 31370000000 | G41: 34550000000
B42: SellingGeneralAndAdministration | D42: 25094000000 | E42: 24932000000 | F42: 26097000000 | G42: 27601000000
... B48: TotalRevenue | D48: 394328000000 | E48: 383285000000 | F48: 391035000000 | G48: 416161000000
B52: Reported balance sheet | C52: Reported balance sheet | D52: Reported balance sheet | E52: Reported balance sheet | F52: Reported balance sheet | G52: Reported balance sheet | H52: Reported balance sheet
...
